Workbook

Sheet README
B2: Private Markets Allocation Model
B3: Selina Hach, October 2026
B5: What this file does
B6: I start with a 60/40 portfolio (60% stocks, 40% bonds) and move 10%, 20% or 30% of it into private credit, private equity, real estate and infrastructure. The file shows what each one adds, the best way to split the money, and how much of the benefit is left when that money is locked up for 3 years.
B8: How to read it
B9: Blue numbers are inputs.
B10: Black numbers are formulas.
B11: Green numbers are formulas that pull from another tab.
B12: Yellow cells are my assumptions: change one and the formulas update on their own.
B14: Tabs
B15: Inputs | C15: Return, risk and correlation for each asset, plus my assumptions.
B16: Covariance | C16: How much each pair of assets moves together, built from the inputs.
B17: Sleeve_Test | C17: The standalone effect of each strategy on return, volatility and Sharpe.
B18: Portfolios | C18: The max-Sharpe split across the four strategies (Private credit, Private equity, Real estate, Infrastructure) with a cap on each.
B19: Lockup | C19: How a 3-year lockup and a 15% cash buffer change the result, and the largest private allocation that still fits
B20: Frontier | C20: The highest return you can get at each level of risk.
B22: Where the numbers come from
B23: Return, risk and correlation: J.P. Morgan 2026 Long-Term Capital Market Assumptions, as of 9/30/2025 (am.jpmorgan.com, LTCMA 2026 USD matrix).
B24: The limit on each strategy, the 15% cash buffer, the 3-year lockup and the 5% limit on going over budget are my own assumptions.
B25: The best-mix weights come from the Python code (src/run_model.py). If you change an assumption, rerun the code to update those too.

Sheet Inputs
B1: Capital market assumptions (J.P. Morgan 2026 LTCMA, USD, 10-15 yr)
B3: Asset | C3: ID | D3: Compound return | E3: Arithmetic return | F3: Volatility
B4: Cash | C4: CASH | D4: 0.031 | E4: 0.031 | F4: 0.0067
B5: US agg bonds | C5: AGG | D5: 0.048 | E5: 0.0491 | F5: 0.0476
B6: US large cap | C6: LC | D6: 0.067 | E6: 0.0794 | F6: 0.1647
B7: Private credit | C7: PC | D7: 0.077 | E7: 0.0859 | F7: 0.1401
B8: Private equity | C8: PE | D8: 0.102 | E8: 0.1191 | F8: 0.1978
B9: Real estate | C9: RE | D9: 0.082 | E9: 0.0879 | F9: 0.1139
B10: Infrastructure | C10: INF | D10: 0.065 | E10: 0.0699 | F10: 0.1025
B13: Correlation matrix
C14: CASH | D14: AGG | E14: LC | F14: PC | G14: PE | H14: RE | I14: INF
B15: CASH | C15: 1 | D15: 0.1 | E15: 0.01 | F15: -0.06 | G15: -0.01 | H15: -0.12 | I15: 0.04
B16: AGG | C16: 0.1 | D16: 1 | E16: 0.3 | F16: 0.07 | G16: 0.01 | H16: -0.15 | I16: 0.06
B17: LC | C17: 0.01 | D17: 0.3 | E17: 1 | F17: 0.55 | G17: 0.75 | H17: 0.35 | I17: 0.47
B18: PC | C18: -0.06 | D18: 0.07 | E18: 0.55 | F18: 1 | G18: 0.66 | H18: 0.35 | I18: 0.42
B19: PE | C19: -0.01 | D19: 0.01 | E19: 0.75 | F19: 0.66 | G19: 1 | H19: 0.32 | I19: 0.62
B20: RE | C20: -0.12 | D20: -0.15 | E20: 0.35 | F20: 0.35 | G20: 0.32 | H20: 1 | I20: 0.29
B21: INF | C21: 0.04 | D21: 0.06 | E21: 0.47 | F21: 0.42 | G21: 0.62 | H21: 0.29 | I21: 1
B22: Key reads (highlighted: each private strategy vs. stocks and bonds) Private equity tracks US large cap closely (0.75): adds return, little diversification. Real estate is the best diversifier: 0.35 with stocks, −0.15 with bonds, 0.30 with the 60/40. Private credit (0.55) and infrastructure (0.47) sit in between. Within privates, PE, credit and infrastructure move together (0.42 to 0.66); real estate stays low (0.29 to 0.35).
B25: Policy levers (my assumptions)
B26: Baseline weight: US large cap | C26: 0.6
B27: Baseline weight: US agg bonds | C27: 0.4
B28: Liquidity floor (cash share of each private sleeve) | C28: 0.15
B29: Illiquidity budget: private credit | C29: 0.12
B30: Illiquidity budget: private equity | C30: 0.07
B31: Illiquidity budget: real estate | C31: 0.08
B32: Illiquidity budget: infrastructure | C32: 0.08
B33: Lockup (quarters) | C33: 12
B34: Allowed breach probability | C34: 0.05
B36: Changing a lever recalculates every formula tab. Optimizer weights and simulation results need a re-run of run_model.py.

Sheet Covariance
B1: Covariance = vol(i) x vol(j) x correlation(i, j)
C2: CASH | D2: AGG | E2: LC | F2: PC | G2: PE | H2: RE | I2: INF
B3: CASH | C3: =Inputs!$F$4*Inputs!$F$4*Inputs!C15 -> 4.489e-05 | D3: =Inputs!$F$4*Inputs!$F$5*Inputs!D15 -> 3.1892e-05 | E3: =Inputs!$F$4*Inputs!$F$6*Inputs!E15 -> 1.10349e-05 | F3: =Inputs!$F$4*Inputs!$F$7*Inputs!F15 -> -5.63202e-05 | G3: =Inputs!$F$4*Inputs!$F$8*Inputs!G15 -> -1.32526e-05 | H3: =Inputs!$F$4*Inputs!$F$9*Inputs!H15 -> -9.15756e-05 | I3: =Inputs!$F$4*Inputs!$F$10*Inputs!I15 -> 2.747e-05
B4: AGG | C4: =Inputs!$F$5*Inputs!$F$4*Inputs!C16 -> 3.1892e-05 | D4: =Inputs!$F$5*Inputs!$F$5*Inputs!D16 -> 0.00226576 | E4: =Inputs!$F$5*Inputs!$F$6*Inputs!E16 -> 0.002351916 | F4: =Inputs!$F$5*Inputs!$F$7*Inputs!F16 -> 0.0004668132 | G4: =Inputs!$F$5*Inputs!$F$8*Inputs!G16 -> 9.41528e-05 | H4: =Inputs!$F$5*Inputs!$F$9*Inputs!H16 -> -0.000813246 | I4: =Inputs!$F$5*Inputs!$F$10*Inputs!I16 -> 0.00029274
B5: LC | C5: =Inputs!$F$6*Inputs!$F$4*Inputs!C17 -> 1.10349e-05 | D5: =Inputs!$F$6*Inputs!$F$5*Inputs!D17 -> 0.002351916 | E5: =Inputs!$F$6*Inputs!$F$6*Inputs!E17 -> 0.02712609 | F5: =Inputs!$F$6*Inputs!$F$7*Inputs!F17 -> 0.012690959 | G5: =Inputs!$F$6*Inputs!$F$8*Inputs!G17 -> 0.024433245 | H5: =Inputs!$F$6*Inputs!$F$9*Inputs!H17 -> 0.0065657655 | I5: =Inputs!$F$6*Inputs!$F$10*Inputs!I17 -> 0.0079344225
B6: PC | C6: =Inputs!$F$7*Inputs!$F$4*Inputs!C18 -> -5.63202e-05 | D6: =Inputs!$F$7*Inputs!$F$5*Inputs!D18 -> 0.0004668132 | E6: =Inputs!$F$7*Inputs!$F$6*Inputs!E18 -> 0.012690959 | F6: =Inputs!$F$7*Inputs!$F$7*Inputs!F18 -> 0.01962801 | G6: =Inputs!$F$7*Inputs!$F$8*Inputs!G18 -> 0.018289775 | H6: =Inputs!$F$7*Inputs!$F$9*Inputs!H18 -> 0.0055850865 | I6: =Inputs!$F$7*Inputs!$F$10*Inputs!I18 -> 0.006031305
B7: PE | C7: =Inputs!$F$8*Inputs!$F$4*Inputs!C19 -> -1.32526e-05 | D7: =Inputs!$F$8*Inputs!$F$5*Inputs!D19 -> 9.41528e-05 | E7: =Inputs!$F$8*Inputs!$F$6*Inputs!E19 -> 0.024433245 | F7: =Inputs!$F$8*Inputs!$F$7*Inputs!F19 -> 0.018289775 | G7: =Inputs!$F$8*Inputs!$F$8*Inputs!G19 -> 0.03912484 | H7: =Inputs!$F$8*Inputs!$F$9*Inputs!H19 -> 0.0072094144 | I7: =Inputs!$F$8*Inputs!$F$10*Inputs!I19 -> 0.01257019
B8: RE | C8: =Inputs!$F$9*Inputs!$F$4*Inputs!C20 -> -9.15756e-05 | D8: =Inputs!$F$9*Inputs!$F$5*Inputs!D20 -> -0.000813246 | E8: =Inputs!$F$9*Inputs!$F$6*Inputs!E20 -> 0.0065657655 | F8: =Inputs!$F$9*Inputs!$F$7*Inputs!F20 -> 0.0055850865 | G8: =Inputs!$F$9*Inputs!$F$8*Inputs!G20 -> 0.0072094144 | H8: =Inputs!$F$9*Inputs!$F$9*Inputs!H20 -> 0.01297321 | I8: =Inputs!$F$9*Inputs!$F$10*Inputs!I20 -> 0.0033856775
B9: INF | C9: =Inputs!$F$10*Inputs!$F$4*Inputs!C21 -> 2.747e-05 | D9: =Inputs!$F$10*Inputs!$F$5*Inputs!D21 -> 0.00029274 | E9: =Inputs!$F$10*Inputs!$F$6*Inputs!E21 -> 0.0079344225 | F9: =Inputs!$F$10*Inputs!$F$7*Inputs!F21 -> 0.006031305 | G9: =Inputs!$F$10*Inputs!$F$8*Inputs!G21 -> 0.01257019 | H9: =Inputs!$F$10*Inputs!$F$9*Inputs!H21 -> 0.0033856775 | I9: =Inputs!$F$10*Inputs!$F$10*Inputs!I21 -> 0.01050625
B12: Liquidity floor: each private sleeve = (1 - floor) asset + floor cash
B13: Each private sleeve holds 15% in cash to meet redemptions. Adjusted return = 85% × asset return + 15% × cash
B14: Asset | C14: Asset share (a) | D14: Cash share (c) | E14: Adj. arithmetic return | F14: Return given up
B15: CASH | C15: 1 | D15: 0 | E15: =C15*Inputs!$E$4+D15*Inputs!$E$4 -> 0.031 | F15: =Inputs!E4-Covariance!E15 -> 0
B16: AGG | C16: 1 | D16: 0 | E16: =C16*Inputs!$E$5+D16*Inputs!$E$4 -> 0.0491 | F16: =Inputs!E5-Covariance!E16 -> 0
B17: LC | C17: 1 | D17: 0 | E17: =C17*Inputs!$E$6+D17*Inputs!$E$4 -> 0.0794 | F17: =Inputs!E6-Covariance!E17 -> 0
B18: PC | C18: =1-Inputs!$C$28 -> 0.85 | D18: =Inputs!$C$28 -> 0.15 | E18: =C18*Inputs!$E$7+D18*Inputs!$E$4 -> 0.077665 | F18: =Inputs!E7-Covariance!E18 -> 0.008235
B19: PE | C19: =1-Inputs!$C$28 -> 0.85 | D19: =Inputs!$C$28 -> 0.15 | E19: =C19*Inputs!$E$8+D19*Inputs!$E$4 -> 0.105885 | F19: =Inputs!E8-Covariance!E19 -> 0.013215
B20: RE | C20: =1-Inputs!$C$28 -> 0.85 | D20: =Inputs!$C$28 -> 0.15 | E20: =C20*Inputs!$E$9+D20*Inputs!$E$4 -> 0.079365 | F20: =Inputs!E9-Covariance!E20 -> 0.008535
B21: INF | C21: =1-Inputs!$C$28 -> 0.85 | D21: =Inputs!$C$28 -> 0.15 | E21: =C21*Inputs!$E$10+D21*Inputs!$E$4 -> 0.064065 | F21: =Inputs!E10-Covariance!E21 -> 0.005835
B23: Covariance after the liquidity floor
B24: adj(i,j) = a_i a_j cov(i,j) + a_i c_j cov(i,cash) + c_i a_j cov(cash,j) + c_i c_j cov(cash,cash)
C25: CASH | D25: AGG | E25: LC | F25: PC | G25: PE | H25: RE | I25: INF
B26: CASH | C26: =$C$15*$C$15*C3+$C$15*$D$15*$C$3+$D$15*$C$15*C$3+$D$15*$D$15*$C$3 -> 4.489e-05 | D26: =$C$15*$C$16*D3+$C$15*$D$16*$C$3+$D$15*$C$16*D$3+$D$15*$D$16*$C$3 -> 3.1892e-05 | E26: =$C$15*$C$17*E3+$C$15*$D$17*$C$3+$D$15*$C$17*E$3+$D$15*$D$17*$C$3 -> 1.10349e-05 | F26: =$C$15*$C$18*F3+$C$15*$D$18*$C$3+$D$15*$C$18*F$3+$D$15*$D$18*$C$3 -> -4.113867e-05 | G26: =$C$15*$C$19*G3+$C$15*$D$19*$C$3+$D$15*$C$19*G$3+$D$15*$D$19*$C$3 -> -4.53121e-06 | H26: =$C$15*$C$20*H3+$C$15*$D$20*$C$3+$D$15*$C$20*H$3+$D$15*$D$20*$C$3 -> -7.110576e-05 | I26: =$C$15*$C$21*I3+$C$15*$D$21*$C$3+$D$15*$C$21*I$3+$D$15*$D$21*$C$3 -> 3.0083e-05
B27: AGG | C27: =$C$16*$C$15*C4+$C$16*$D$15*$C$4+$D$16*$C$15*C$3+$D$16*$D$15*$C$3 -> 3.1892e-05 | D27: =$C$16*$C$16*D4+$C$16*$D$16*$C$4+$D$16*$C$16*D$3+$D$16*$D$16*$C$3 -> 0.00226576 | E27: =$C$16*$C$17*E4+$C$16*$D$17*$C$4+$D$16*$C$17*E$3+$D$16*$D$17*$C$3 -> 0.002351916 | F27: =$C$16*$C$18*F4+$C$16*$D$18*$C$4+$D$16*$C$18*F$3+$D$16*$D$18*$C$3 -> 0.00040157502 | G27: =$C$16*$C$19*G4+$C$16*$D$19*$C$4+$D$16*$C$19*G$3+$D$16*$D$19*$C$3 -> 8.481368e-05 | H27: =$C$16*$C$20*H4+$C$16*$D$20*$C$4+$D$16*$C$20*H$3+$D$16*$D$20*$C$3 -> -0.0006864753 | I27: =$C$16*$C$21*I4+$C$16*$D$21*$C$4+$D$16*$C$21*I$3+$D$16*$D$21*$C$3 -> 0.0002536128
B28: LC | C28: =$C$17*$C$15*C5+$C$17*$D$15*$C$5+$D$17*$C$15*C$3+$D$17*$D$15*$C$3 -> 1.10349e-05 | D28: =$C$17*$C$16*D5+$C$17*$D$16*$C$5+$D$17*$C$16*D$3+$D$17*$D$16*$C$3 -> 0.002351916 | E28: =$C$17*$C$17*E5+$C$17*$D$17*$C$5+$D$17*$C$17*E$3+$D$17*$D$17*$C$3 -> 0.02712609 | F28: =$C$17*$C$18*F5+$C$17*$D$18*$C$5+$D$17*$C$18*F$3+$D$17*$D$18*$C$3 -> 0.01078897 | G28: =$C$17*$C$19*G5+$C$17*$D$19*$C$5+$D$17*$C$19*G$3+$D$17*$D$19*$C$3 -> 0.020769913 | H28: =$C$17*$C$20*H5+$C$17*$D$20*$C$5+$D$17*$C$20*H$3+$D$17*$D$20*$C$3 -> 0.0055825559 | I28: =$C$17*$C$21*I5+$C$17*$D$21*$C$5+$D$17*$C$21*I$3+$D$17*$D$21*$C$3 -> 0.0067459144
B29: PC | C29: =$C$18*$C$15*C6+$C$18*$D$15*$C$6+$D$18*$C$15*C$3+$D$18*$D$15*$C$3 -> -4.113867e-05 | D29: =$C$18*$C$16*D6+$C$18*$D$16*$C$6+$D$18*$C$16*D$3+$D$18*$D$16*$C$3 -> 0.00040157502 | E29: =$C$18*$C$17*E6+$C$18*$D$17*$C$6+$D$18*$C$17*E$3+$D$18*$D$17*$C$3 -> 0.01078897 | F29: =$C$18*$C$18*F6+$C$18*$D$18*$C$6+$D$18*$C$18*F$3+$D$18*$D$18*$C$3 -> 0.014167886 | G29: =$C$18*$C$19*G6+$C$18*$D$19*$C$6+$D$18*$C$19*G$3+$D$18*$D$19*$C$3 -> 0.013206502 | H29: =$C$18*$C$20*H6+$C$18*$D$20*$C$6+$D$18*$C$20*H$3+$D$18*$D$20*$C$3 -> 0.0040173783 | I29: =$C$18*$C$21*I6+$C$18*$D$21*$C$6+$D$18*$C$21*I$3+$D$18*$D$21*$C$3 -> 0.0043549495
B30: PE | C30: =$C$19*$C$15*C7+$C$19*$D$15*$C$7+$D$19*$C$15*C$3+$D$19*$D$15*$C$3 -> -4.53121e-06 | D30: =$C$19*$C$16*D7+$C$19*$D$16*$C$7+$D$19*$C$16*D$3+$D$19*$D$16*$C$3 -> 8.481368e-05 | E30: =$C$19*$C$17*E7+$C$19*$D$17*$C$7+$D$19*$C$17*E$3+$D$19*$D$17*$C$3 -> 0.020769913 | F30: =$C$19*$C$18*F7+$C$19*$D$18*$C$7+$D$19*$C$18*F$3+$D$19*$D$18*$C$3 -> 0.013206502 | G30: =$C$19*$C$19*G7+$C$19*$D$19*$C$7+$D$19*$C$19*G$3+$D$19*$D$19*$C$3 -> 0.028265328 | H30: =$C$19*$C$20*H7+$C$19*$D$20*$C$7+$D$19*$C$20*H$3+$D$19*$D$20*$C$3 -> 0.0051964463 | I30: =$C$19*$C$21*I7+$C$19*$D$21*$C$7+$D$19*$C$21*I$3+$D$19*$D$21*$C$3 -> 0.009084785
B31: RE | C31: =$C$20*$C$15*C8+$C$20*$D$15*$C$8+$D$20*$C$15*C$3+$D$20*$D$15*$C$3 -> -7.110576e-05 | D31: =$C$20*$C$16*D8+$C$20*$D$16*$C$8+$D$20*$C$16*D$3+$D$20*$D$16*$C$3 -> -0.0006864753 | E31: =$C$20*$C$17*E8+$C$20*$D$17*$C$8+$D$20*$C$17*E$3+$D$20*$D$17*$C$3 -> 0.0055825559 | F31: =$C$20*$C$18*F8+$C$20*$D$18*$C$8+$D$20*$C$18*F$3+$D$20*$D$18*$C$3 -> 0.0040173783 | G31: =$C$20*$C$19*G8+$C$20*$D$19*$C$8+$D$20*$C$19*G$3+$D$20*$D$19*$C$3 -> 0.0051964463 | H31: =$C$20*$C$20*H8+$C$20*$D$20*$C$8+$D$20*$C$20*H$3+$D$20*$D$20*$C$3 -> 0.0093508025 | I31: =$C$20*$C$21*I8+$C$20*$D$21*$C$8+$D$20*$C$21*I$3+$D$20*$D$21*$C$3 -> 0.0024389886
B32: INF | C32: =$C$21*$C$15*C9+$C$21*$D$15*$C$9+$D$21*$C$15*C$3+$D$21*$D$15*$C$3 -> 3.0083e-05 | D32: =$C$21*$C$16*D9+$C$21*$D$16*$C$9+$D$21*$C$16*D$3+$D$21*$D$16*$C$3 -> 0.0002536128 | E32: =$C$21*$C$17*E9+$C$21*$D$17*$C$9+$D$21*$C$17*E$3+$D$21*$D$17*$C$3 -> 0.0067459144 | F32: =$C$21*$C$18*F9+$C$21*$D$18*$C$9+$D$21*$C$18*F$3+$D$21*$D$18*$C$3 -> 0.0043549495 | G32: =$C$21*$C$19*G9+$C$21*$D$19*$C$9+$D$21*$C$19*G$3+$D$21*$D$19*$C$3 -> 0.009084785 | H32: =$C$21*$C$20*H9+$C$21*$D$20*$C$9+$D$21*$C$20*H$3+$D$21*$D$20*$C$3 -> 0.0024389886 | I32: =$C$21*$C$21*I9+$C$21*$D$21*$C$9+$D$21*$C$21*I$3+$D$21*$D$21*$C$3 -> 0.0075987805
B35: Portfolio risk depends on how much each pair of assets moves together. • The top table shows that for the original assets. • The two tables below show what changes when each private sleeve keeps 15% in cash: return goes down, and risk goes down too.

Sheet Sleeve_Test
B1: Replace X% of the 60/40 with ONE sleeve (all formulas)
B3: 60/40 return | C3: =Inputs!$C$26*Inputs!$E$6+Inputs!$C$27*Inputs!$E$5 -> 0.06728
B4: 60/40 variance | C4: =Inputs!$C$26^2*Inputs!$F$6^2+Inputs!$C$27^2*Inputs!$F$5^2+2*Inputs!$C$26*Inputs!$C$27*Covariance!D5 -> 0.011256834
B5: 60/40 volatility | C5: =SQRT(C4) -> 0.10609823
B6: 60/40 Sharpe | C6: =(C3-Inputs!$E$4)/C5 -> 0.34194728
B8: Baseline: the 60/40 with no private allocation. All “change” columns below are measured against this benchmark.
B11: Funding (pro rata) | D11: US large cap | E11: US agg bonds
B12: 60/40 | D12: 0.6 | E12: 0.4
B13: Private | C13: 0.1 | D13: =$D$12-($D$12*C13) -> 0.54 | E13: =$E$12-($E$12*C13) -> 0.36
C14: 0.2 | D14: =$D$12-($D$12*C14) -> 0.48 | E14: =$E$12-($E$12*C14) -> 0.32
C15: 0.3 | D15: =$D$12-($D$12*C15) -> 0.42 | E15: =$E$12-($E$12*C15) -> 0.28
B17: Sleeve | C17: Allocation X | D17: Cov(sleeve, 60/40) | E17: Corr with 60/40 | F17: Return | G17: Volatility | H17: Sharpe | I17: Change in return | J17: Change in vol | K17: Change in Sharpe | L17: Lockstep vol | M17: Diversification
B18: Private credit | C18: 0.1 | D18: =Inputs!$C$26*Covariance!F5+Inputs!$C$27*Covariance!F4 -> 0.0078013004 | E18: =D18/(Inputs!$F$7*$C$5) -> 0.52483252 | F18: =(1-C18)*$C$3+C18*Inputs!$E$7 -> 0.069142 | G18: =SQRT((1-C18)^2*$C$4+C18^2*Inputs!$F$7^2+2*C18*(1-C18)*D18) -> 0.10353043 | H18: =(F18-Inputs!$E$4)/G18 -> 0.36841343 | I18: =(F18-$C$3)*10000 -> 18.62 | J18: =(G18-$C$5)*10000 -> -25.677989 | K18: =H18-$C$6 -> 0.02646615 | L18: =(1-C18)*$C$5+C18*Inputs!$F$7 -> 0.1094984 | M18: =(L18-G18)*10000 -> 59.679763
B19: Private credit | C19: 0.2 | D19: =Inputs!$C$26*Covariance!F5+Inputs!$C$27*Covariance!F4 -> 0.0078013004 | E19: =D19/(Inputs!$F$7*$C$5) -> 0.52483252 | F19: =(1-C19)*$C$3+C19*Inputs!$E$7 -> 0.071004 | G19: =SQRT((1-C19)^2*$C$4+C19^2*Inputs!$F$7^2+2*C19*(1-C19)*D19) -> 0.10240073 | H19: =(F19-Inputs!$E$4)/G19 -> 0.39066127 | I19: =(F19-$C$3)*10000 -> 37.24 | J19: =(G19-$C$5)*10000 -> -36.974938 | K19: =H19-$C$6 -> 0.048713987 | L19: =(1-C19)*$C$5+C19*Inputs!$F$7 -> 0.11289858 | M19: =(L19-G19)*10000 -> 104.97848
B20: Private credit | C20: 0.3 | D20: =Inputs!$C$26*Covariance!F5+Inputs!$C$27*Covariance!F4 -> 0.0078013004 | E20: =D20/(Inputs!$F$7*$C$5) -> 0.52483252 | F20: =(1-C20)*$C$3+C20*Inputs!$E$7 -> 0.072866 | G20: =SQRT((1-C20)^2*$C$4+C20^2*Inputs!$F$7^2+2*C20*(1-C20)*D20) -> 0.10275658 | H20: =(F20-Inputs!$E$4)/G20 -> 0.40742888 | I20: =(F20-$C$3)*10000 -> 55.86 | J20: =(G20-$C$5)*10000 -> -33.416425 | K20: =H20-$C$6 -> 0.0654816 | L20: =(1-C20)*$C$5+C20*Inputs!$F$7 -> 0.11629876 | M20: =(L20-G20)*10000 -> 135.42175 | O20: Real estate saves the most risk at every allocation
B21: Private equity | C21: 0.1 | D21: =Inputs!$C$26*Covariance!G5+Inputs!$C$27*Covariance!G4 -> 0.014697608 | E21: =D21/(Inputs!$F$8*$C$5) -> 0.70034535 | F21: =(1-C21)*$C$3+C21*Inputs!$E$8 -> 0.072462 | G21: =SQRT((1-C21)^2*$C$4+C21^2*Inputs!$F$8^2+2*C21*(1-C21)*D21) -> 0.11024905 | H21: =(F21-Inputs!$E$4)/G21 -> 0.3760758 | I21: =(F21-$C$3)*10000 -> 51.82 | J21: =(G21-$C$5)*10000 -> 41.50824 | K21: =H21-$C$6 -> 0.034128521 | L21: =(1-C21)*$C$5+C21*Inputs!$F$8 -> 0.1152684 | M21: =(L21-G21)*10000 -> 50.193534 | O21: Volatility saved vs. a sleeve that moved in lockstep with the 60/40 (bps)
B22: Private equity | C22: 0.2 | D22: =Inputs!$C$26*Covariance!G5+Inputs!$C$27*Covariance!G4 -> 0.014697608 | E22: =D22/(Inputs!$F$8*$C$5) -> 0.70034535 | F22: =(1-C22)*$C$3+C22*Inputs!$E$8 -> 0.077644 | G22: =SQRT((1-C22)^2*$C$4+C22^2*Inputs!$F$8^2+2*C22*(1-C22)*D22) -> 0.11607154 | H22: =(F22-Inputs!$E$4)/G22 -> 0.40185562 | I22: =(F22-$C$3)*10000 -> 103.64 | J22: =(G22-$C$5)*10000 -> 99.733107 | K22: =H22-$C$6 -> 0.059908344 | L22: =(1-C22)*$C$5+C22*Inputs!$F$8 -> 0.12443858 | M22: =(L22-G22)*10000 -> 83.67044
B23: Private equity | C23: 0.3 | D23: =Inputs!$C$26*Covariance!G5+Inputs!$C$27*Covariance!G4 -> 0.014697608 | E23: =D23/(Inputs!$F$8*$C$5) -> 0.70034535 | F23: =(1-C23)*$C$3+C23*Inputs!$E$8 -> 0.082826 | G23: =SQRT((1-C23)^2*$C$4+C23^2*Inputs!$F$8^2+2*C23*(1-C23)*D23) -> 0.12332915 | H23: =(F23-Inputs!$E$4)/G23 -> 0.42022506 | I23: =(F23-$C$3)*10000 -> 155.46 | J23: =(G23-$C$5)*10000 -> 172.30925 | K23: =H23-$C$6 -> 0.07827778 | L23: =(1-C23)*$C$5+C23*Inputs!$F$8 -> 0.13360876 | M23: =(L23-G23)*10000 -> 102.79607
B24: Real estate | C24: 0.1 | D24: =Inputs!$C$26*Covariance!H5+Inputs!$C$27*Covariance!H4 -> 0.0036141609 | E24: =D24/(Inputs!$F$9*$C$5) -> 0.29907192 | F24: =(1-C24)*$C$3+C24*Inputs!$E$9 -> 0.069342 | G24: =SQRT((1-C24)^2*$C$4+C24^2*Inputs!$F$9^2+2*C24*(1-C24)*D24) -> 0.099490283 | H24: =(F24-Inputs!$E$4)/G24 -> 0.38538437 | I24: =(F24-$C$3)*10000 -> 20.62 | J24: =(G24-$C$5)*10000 -> -66.079439 | K24: =H24-$C$6 -> 0.043437091 | L24: =(1-C24)*$C$5+C24*Inputs!$F$9 -> 0.1068784 | M24: =(L24-G24)*10000 -> 73.881213
B25: Real estate | C25: 0.2 | D25: =Inputs!$C$26*Covariance!H5+Inputs!$C$27*Covariance!H4 -> 0.0036141609 | E25: =D25/(Inputs!$F$9*$C$5) -> 0.29907192 | F25: =(1-C25)*$C$3+C25*Inputs!$E$9 -> 0.071404 | G25: =SQRT((1-C25)^2*$C$4+C25^2*Inputs!$F$9^2+2*C25*(1-C25)*D25) -> 0.094232868 | H25: =(F25-Inputs!$E$4)/G25 -> 0.42876759 | I25: =(F25-$C$3)*10000 -> 41.24 | J25: =(G25-$C$5)*10000 -> -118.65358 | K25: =H25-$C$6 -> 0.086820312 | L25: =(1-C25)*$C$5+C25*Inputs!$F$9 -> 0.10765858 | M25: =(L25-G25)*10000 -> 134.25713
B26: Real estate | C26: 0.3 | D26: =Inputs!$C$26*Covariance!H5+Inputs!$C$27*Covariance!H4 -> 0.0036141609 | E26: =D26/(Inputs!$F$9*$C$5) -> 0.29907192 | F26: =(1-C26)*$C$3+C26*Inputs!$E$9 -> 0.073466 | G26: =SQRT((1-C26)^2*$C$4+C26^2*Inputs!$F$9^2+2*C26*(1-C26)*D26) -> 0.090561498 | H26: =(F26-Inputs!$E$4)/G26 -> 0.46891892 | I26: =(F26-$C$3)*10000 -> 61.86 | J26: =(G26-$C$5)*10000 -> -155.36728 | K26: =H26-$C$6 -> 0.12697164 | L26: =(1-C26)*$C$5+C26*Inputs!$F$9 -> 0.10843876 | M26: =(L26-G26)*10000 -> 178.7726
B27: Infrastructure | C27: 0.1 | D27: =Inputs!$C$26*Covariance!I5+Inputs!$C$27*Covariance!I4 -> 0.0048777495 | E27: =D27/(Inputs!$F$10*$C$5) -> 0.44852588 | F27: =(1-C27)*$C$3+C27*Inputs!$E$10 -> 0.067542 | G27: =SQRT((1-C27)^2*$C$4+C27^2*Inputs!$F$10^2+2*C27*(1-C27)*D27) -> 0.10050419 | H27: =(F27-Inputs!$E$4)/G27 -> 0.36358682 | I27: =(F27-$C$3)*10000 -> 2.62 | J27: =(G27-$C$5)*10000 -> -55.940342 | K27: =H27-$C$6 -> 0.021639543 | L27: =(1-C27)*$C$5+C27*Inputs!$F$10 -> 0.1057384 | M27: =(L27-G27)*10000 -> 52.342115
B28: Infrastructure | C28: 0.2 | D28: =Inputs!$C$26*Covariance!I5+Inputs!$C$27*Covariance!I4 -> 0.0048777495 | E28: =D28/(Inputs!$F$10*$C$5) -> 0.44852588 | F28: =(1-C28)*$C$3+C28*Inputs!$E$10 -> 0.067804 | G28: =SQRT((1-C28)^2*$C$4+C28^2*Inputs!$F$10^2+2*C28*(1-C28)*D28) -> 0.095841032 | H28: =(F28-Inputs!$E$4)/G28 -> 0.38401089 | I28: =(F28-$C$3)*10000 -> 5.24 | J28: =(G28-$C$5)*10000 -> -102.57195 | K28: =H28-$C$6 -> 0.04206361 | L28: =(1-C28)*$C$5+C28*Inputs!$F$10 -> 0.10537858 | M28: =(L28-G28)*10000 -> 95.375494
B29: Infrastructure | C29: 0.3 | D29: =Inputs!$C$26*Covariance!I5+Inputs!$C$27*Covariance!I4 -> 0.0048777495 | E29: =D29/(Inputs!$F$10*$C$5) -> 0.44852588 | F29: =(1-C29)*$C$3+C29*Inputs!$E$10 -> 0.068066 | G29: =SQRT((1-C29)^2*$C$4+C29^2*Inputs!$F$10^2+2*C29*(1-C29)*D29) -> 0.092250018 | H29: =(F29-Inputs!$E$4)/G29 -> 0.40179938 | I29: =(F29-$C$3)*10000 -> 7.86 | J29: =(G29-$C$5)*10000 -> -138.48209 | K29: =H29-$C$6 -> 0.0598521 | L29: =(1-C29)*$C$5+C29*Inputs!$F$10 -> 0.10501876 | M29: =(L29-G29)*10000 -> 127.68741
B31: Lockstep vol = volatility if the sleeve were perfectly correlated with the 60/40. Diversification = lockstep vol minus actual vol.
B33: Chart data (links to the table above)
B34: Diversification (bps) | C34: 10% allocation | D34: 20% allocation | E34: 30% allocation
B35: Private credit | C35: =M18 -> 59.679763 | D35: =M19 -> 104.97848 | E35: =M20 -> 135.42175
B36: Private equity | C36: =M21 -> 50.193534 | D36: =M22 -> 83.67044 | E36: =M23 -> 102.79607
B37: Real estate | C37: =M24 -> 73.881213 | D37: =M25 -> 134.25713 | E37: =M26 -> 178.7726
B38: Infrastructure | C38: =M27 -> 52.342115 | D38: =M28 -> 95.375494 | E38: =M29 -> 127.68741
B40: Real estate saves the most risk at every allocation
B43: At 20% allocation | C43: Change in return | D43: Change in vol
B44: Private credit | C44: =I19 -> 37.24 | D44: =J19 -> -36.974938
B45: Private equity | C45: =I22 -> 103.64 | D45: =J22 -> 99.733107
B46: Real estate | C46: =I25 -> 41.24 | D46: =J25 -> -118.65358
B47: Infrastructure | C47: =I28 -> 5.24 | D47: =J28 -> -102.57195
B49: At 20%, private equity adds the most return but is the only sleeve that raises risk | O49: At 20%, private equity adds the most return but is the only sleeve that raises risk
O50: Change vs. the 60/40 (bps)

Sheet Portfolios
B1: Portfolio math (formulas). Weights in blue are the Python optimizer output.
B2: Lockup-safe columns use the liquidity-floor returns and covariance.
B5: Weights | C5: 60/40 | D5: 10% private | E5: 20% private | F5: 30% private | G5: 10% lockup-safe | H5: 20% lockup-safe
B6: Cash | C6: 0 | D6: 0 | E6: 0 | F6: 0 | G6: 0 | H6: 0
B7: US agg bonds | C7: =Inputs!$C$27 -> 0.4 | D7: 0.36 | E7: 0.32 | F7: 0.28 | G7: 0.36 | H7: 0.32
B8: US large cap | C8: =Inputs!$C$26 -> 0.6 | D8: 0.54 | E8: 0.48 | F8: 0.42 | G8: 0.54 | H8: 0.48
B9: Private credit | C9: 0 | D9: 0 | E9: 0.05 | F9: 0.092575 | G9: 0 | H9: 0.087115
B10: Private equity | C10: 0 | D10: 0.02 | E10: 0.07 | F10: 0.07 | G10: 0.045845 | H10: 0.04674
B11: Real estate | C11: 0 | D11: 0.08 | E11: 0.08 | F11: 0.08 | G11: 0.054155 | H11: 0.055507
B12: Infrastructure | C12: 0 | D12: 0 | E12: 0 | F12: 0.057425 | G12: 0 | H12: 0.010638
B13: Total | C13: =SUM(C6:C12) -> 1 | D13: =SUM(D6:D12) -> 1 | E13: =SUM(E6:E12) -> 1 | F13: =SUM(F6:F12) -> 1 | G13: =SUM(G6:G12) -> 1 | H13: =SUM(H6:H12) -> 1
B15: Each column is one portfolio. Stocks and bonds are cut in proportion to fund the private allocation. • Blue = the optimal split of the private allocation (highest Sharpe), found by the Python model, with each strategy under its max limit. • Lockup-safe = same total private allocation, but split differently: each strategy starts below its limit, so it has room to grow during the 3-year lockup without going over. • No 30% lockup-safe column: once every strategy starts below its limit, the total only reaches about 25.6%.
B18: (Covariance x weights), per asset | C18: 60/40 | D18: 10% private | E18: 20% private | F18: 30% private | G18: 10% lockup-safe | H18: 20% lockup-safe
B19: Cash | C19: =SUMPRODUCT(Covariance!$C$3:$C$9,C$6:C$12) -> 1.937774e-05 | D19: =SUMPRODUCT(Covariance!$C$3:$C$9,D$6:D$12) -> 9.848866e-06 | E19: =SUMPRODUCT(Covariance!$C$3:$C$9,E$6:E$12) -> 4.432452e-06 | F19: =SUMPRODUCT(Covariance!$C$3:$C$9,F$6:F$12) -> 1.6743102e-06 | G19: =SUMPRODUCT(Covariance!$C$26:$C$32,G$6:G$12) -> 1.33815e-05 | H19: =SUMPRODUCT(Covariance!$C$26:$C$32,H$6:H$12) -> 8.0797635e-06
B20: US agg bonds | C20: =SUMPRODUCT(Covariance!$D$3:$D$9,C$6:C$12) -> 0.0023174536 | D20: =SUMPRODUCT(Covariance!$D$3:$D$9,D$6:D$12) -> 0.0020225316 | E20: =SUMPRODUCT(Covariance!$D$3:$D$9,E$6:E$12) -> 0.0018188346 | F20: =SUMPRODUCT(Covariance!$D$3:$D$9,F$6:F$12) -> 0.0016237744 | G20: =SUMPRODUCT(Covariance!$D$26:$D$32,G$6:G$12) -> 0.0020524205 | H20: =SUMPRODUCT(Covariance!$D$26:$D$32,H$6:H$12) -> 0.001857504
B21: US large cap | C21: =SUMPRODUCT(Covariance!$E$3:$E$9,C$6:C$12) -> 0.01721642 | D21: =SUMPRODUCT(Covariance!$E$3:$E$9,D$6:D$12) -> 0.016508705 | E21: =SUMPRODUCT(Covariance!$E$3:$E$9,E$6:E$12) -> 0.016643273 | F21: =SUMPRODUCT(Covariance!$E$3:$E$9,F$6:F$12) -> 0.015917582 | G21: =SUMPRODUCT(Covariance!$E$26:$E$32,G$6:G$12) -> 0.016749298 | H21: =SUMPRODUCT(Covariance!$E$26:$E$32,H$6:H$12) -> 0.016065437
B22: Private credit | C22: =SUMPRODUCT(Covariance!$F$3:$F$9,C$6:C$12) -> 0.0078013004 | D22: =SUMPRODUCT(Covariance!$F$3:$F$9,D$6:D$12) -> 0.0078337728 | E22: =SUMPRODUCT(Covariance!$F$3:$F$9,E$6:E$12) -> 0.008949532 | F22: =SUMPRODUCT(Covariance!$F$3:$F$9,F$6:F$12) -> 0.0093514121 | G22: =SUMPRODUCT(Covariance!$F$26:$F$32,G$6:G$12) -> 0.006793624 | H22: =SUMPRODUCT(Covariance!$F$26:$F$32,H$6:H$12) -> 0.0074280374
B23: Private equity | C23: =SUMPRODUCT(Covariance!$G$3:$G$9,C$6:C$12) -> 0.014697608 | D23: =SUMPRODUCT(Covariance!$G$3:$G$9,D$6:D$12) -> 0.014587097 | E23: =SUMPRODUCT(Covariance!$G$3:$G$9,E$6:E$12) -> 0.015988067 | F23: =SUMPRODUCT(Covariance!$G$3:$G$9,F$6:F$12) -> 0.016018837 | G23: =SUMPRODUCT(Covariance!$G$26:$G$32,G$6:G$12) -> 0.012823524 | H23: =SUMPRODUCT(Covariance!$G$26:$G$32,H$6:H$12) -> 0.012853388
B24: Real estate | C24: =SUMPRODUCT(Covariance!$H$3:$H$9,C$6:C$12) -> 0.0036141609 | D24: =SUMPRODUCT(Covariance!$H$3:$H$9,D$6:D$12) -> 0.0044347899 | E24: =SUMPRODUCT(Covariance!$H$3:$H$9,E$6:E$12) -> 0.0047130989 | F24: =SUMPRODUCT(Covariance!$H$3:$H$9,F$6:F$12) -> 0.0047838904 | G24: =SUMPRODUCT(Covariance!$H$26:$H$32,G$6:G$12) -> 0.0035120729 | H24: =SUMPRODUCT(Covariance!$H$26:$H$32,H$6:H$12) -> 0.0035977915
B25: Infrastructure | C25: =SUMPRODUCT(Covariance!$I$3:$I$9,C$6:C$12) -> 0.0048777495 | D25: =SUMPRODUCT(Covariance!$I$3:$I$9,D$6:D$12) -> 0.0049122326 | E25: =SUMPRODUCT(Covariance!$I$3:$I$9,E$6:E$12) -> 0.0053545323 | F25: =SUMPRODUCT(Covariance!$I$3:$I$9,F$6:F$12) -> 0.0057268616 | G25: =SUMPRODUCT(Covariance!$I$26:$I$32,G$6:G$12) -> 0.0042826698 | H25: =SUMPRODUCT(Covariance!$I$26:$I$32,H$6:H$12) -> 0.004339416
B27: As this portfolio fluctuates, does this asset move in tandem, and to what extent?
B30: Results | C30: 60/40 | D30: 10% private | E30: 20% private | F30: 30% private | G30: 10% lockup-safe | H30: 20% lockup-safe
B31: Expected return (arithmetic) | C31: =SUMPRODUCT(C$6:C$12,Inputs!$E$4:$E$10) -> 0.06728 | D31: =SUMPRODUCT(D$6:D$12,Inputs!$E$4:$E$10) -> 0.069966 | E31: =SUMPRODUCT(E$6:E$12,Inputs!$E$4:$E$10) -> 0.073488 | F31: =SUMPRODUCT(F$6:F$12,Inputs!$E$4:$E$10) -> 0.0744312 | G31: =SUMPRODUCT(G$6:G$12,Covariance!$E$15:$E$21) -> 0.069704309 | H31: =SUMPRODUCT(H$6:H$12,Covariance!$E$15:$E$21) -> 0.070625688
B32: Variance | C32: =SUMPRODUCT(C$6:C$12,C$19:C$25) -> 0.011256834 | D32: =SUMPRODUCT(D$6:D$12,D$19:D$25) -> 0.010289337 | E32: =SUMPRODUCT(E$6:E$12,E$19:E$25) -> 0.010514487 | F32: =SUMPRODUCT(F$6:F$12,F$19:F$25) -> 0.0098386432 | G32: =SUMPRODUCT(G$6:G$12,G$19:G$25) -> 0.010561583 | H32: =SUMPRODUCT(H$6:H$12,H$19:H$25) -> 0.0097995373
B33: Volatility | C33: =SQRT(C32) -> 0.10609823 | D33: =SQRT(D32) -> 0.10143637 | E33: =SQRT(E32) -> 0.10254017 | F33: =SQRT(F32) -> 0.099189935 | G33: =SQRT(G32) -> 0.10276956 | H33: =SQRT(H32) -> 0.098992612
B34: Sharpe ratio | C34: =(C31-Inputs!$E$4)/C33 -> 0.34194728 | D34: =(D31-Inputs!$E$4)/D33 -> 0.3841423 | E34: =(E31-Inputs!$E$4)/E33 -> 0.41435467 | F34: =(F31-Inputs!$E$4)/F33 -> 0.43785894 | G34: =(G31-Inputs!$E$4)/G33 -> 0.37661257 | H34: =(H31-Inputs!$E$4)/H33 -> 0.40028935
B36: Adding private allocations led to a steady rise in the Sharpe ratio: 0.342 → 0.384 → 0.414 → 0.438. At the same allocation level, the Sharpe ratio was slightly lower when a lockup period was applied: 0.377 versus 0.384 (at the 10% level) and 0.400 versus 0.414 (at the 20% level). This reflects the cost of holding 15% in cash and having to set targets below the limit.
B39: Share of portfolio risk | C39: 60/40 | D39: 10% private | E39: 20% private | F39: 30% private | G39: 10% lockup-safe | H39: 20% lockup-safe
B40: Cash | C40: =C6*C19/C$32 -> 0 | D40: =D6*D19/D$32 -> 0 | E40: =E6*E19/E$32 -> 0 | F40: =F6*F19/F$32 -> 0 | G40: =G6*G19/G$32 -> 0 | H40: =H6*H19/H$32 -> 0
B41: US agg bonds | C41: =C7*C20/C$32 -> 0.082348329 | D41: =D7*D20/D$32 -> 0.070763683 | E41: =E7*E20/E$32 -> 0.055354774 | F41: =F7*F20/F$32 -> 0.046211333 | G41: =G7*G20/G$32 -> 0.06995839 | H41: =H7*H20/H$32 -> 0.060656057
B42: US large cap | C42: =C8*C21/C$32 -> 0.91765167 | D42: =D8*D21/D$32 -> 0.86640184 | E42: =E8*E21/E$32 -> 0.75978702 | F42: =F8*F21/F$32 -> 0.6795027 | G42: =G8*G21/G$32 -> 0.85636982 | H42: =H8*H21/H$32 -> 0.78691571
B43: Private credit | C43: =C9*C22/C$32 -> 0 | D43: =D9*D22/D$32 -> 0 | E43: =E9*E22/E$32 -> 0.0425581 | F43: =F9*F22/F$32 -> 0.087990484 | G43: =G9*G22/G$32 -> 0 | H43: =H9*H22/H$32 -> 0.066033065
B44: Private equity | C44: =C10*C23/C$32 -> 0 | D44: =D10*D23/D$32 -> 0.028353814 | E44: =E10*E23/E$32 -> 0.10644026 | F44: =F10*F23/F$32 -> 0.11397085 | G44: =G10*G23/G$32 -> 0.055663477 | H44: =H10*H23/H$32 -> 0.061305685
B45: Real estate | C45: =C11*C24/C$32 -> 0 | D45: =D11*D24/D$32 -> 0.034480666 | E45: =E11*E24/E$32 -> 0.035859848 | F45: =F11*F24/F$32 -> 0.038898781 | G45: =G11*G24/G$32 -> 0.018008314 | H45: =H11*H24/H$32 -> 0.02037878
B46: Infrastructure | C46: =C12*C25/C$32 -> 0 | D46: =D12*D25/D$32 -> 0 | E46: =E12*E25/E$32 -> 0 | F46: =F12*F25/F$32 -> 0.033425852 | G46: =G12*G25/G$32 -> 0 | H46: =H12*H25/H$32 -> 0.0047107028
B47: Total (should be 100%) | C47: =SUM(C40:C46) -> 1 | D47: =SUM(D40:D46) -> 1 | E47: =SUM(E40:E46) -> 1 | F47: =SUM(F40:F46) -> 1 | G47: =SUM(G40:G46) -> 1 | H47: =SUM(H40:H46) -> 1
B49: Share of total portfolio risk coming from each asset. Compare with the weights above: US large cap is 60% of the 60/40 but 92% of its risk. Private equity takes more risk than its weight; real estate takes less.
B52: Illiquidity budget check | C52: 60/40 | D52: 10% private | E52: 20% private | F52: 30% private | G52: 10% lockup-safe | H52: 20% lockup-safe
B53: Private credit within budget? | C53: =IF(C9<=Inputs!$C$29+0.000001,"OK","OVER") -> OK | D53: =IF(D9<=Inputs!$C$29+0.000001,"OK","OVER") -> OK | E53: =IF(E9<=Inputs!$C$29+0.000001,"OK","OVER") -> OK | F53: =IF(F9<=Inputs!$C$29+0.000001,"OK","OVER") -> OK | G53: =IF(G9<=Inputs!$C$29+0.000001,"OK","OVER") -> OK | H53: =IF(H9<=Inputs!$C$29+0.000001,"OK","OVER") -> OK
B54: Private equity within budget? | C54: =IF(C10<=Inputs!$C$30+0.000001,"OK","OVER") -> OK | D54: =IF(D10<=Inputs!$C$30+0.000001,"OK","OVER") -> OK | E54: =IF(E10<=Inputs!$C$30+0.000001,"OK","OVER") -> OK | F54: =IF(F10<=Inputs!$C$30+0.000001,"OK","OVER") -> OK | G54: =IF(G10<=Inputs!$C$30+0.000001,"OK","OVER") -> OK | H54: =IF(H10<=Inputs!$C$30+0.000001,"OK","OVER") -> OK
...

Sheet Lockup
B1: 3-year lockup: drift headroom from 10,000 simulated paths (Python), budget math in formulas
B2: Headroom = 95th-percentile peak weight / starting weight. A sleeve's target must be its budget divided by its headroom.
B4: 10% private allocation | C4: 0.1
B5: Sleeve | C5: Budget | D5: Headroom (sim) | E5: Effective budget | F5: Lockup-safe weight | G5: Breach prob. (sim)
B6: Private credit | C6: =Inputs!$C$29 -> 0.12 | D6: 1.409509 | E6: =C6/D6 -> 0.08513603 | F6: 0 | G6: 0
B7: Private equity | C7: =Inputs!$C$30 -> 0.07 | D7: 1.525547 | E7: =C7/D7 -> 0.045885181 | F7: 0.045845 | G7: 0.0467
B8: Real estate | C8: =Inputs!$C$31 -> 0.08 | D8: 1.477247 | E8: =C8/D8 -> 0.054154789 | F8: 0.054155 | G8: 0.0444
B9: Infrastructure | C9: =Inputs!$C$32 -> 0.08 | D9: 1.342156 | E9: =C9/D9 -> 0.05960559 | F9: 0 | G9: 0
B10: Max feasible private (sum of effective budgets) | E10: =SUM(E6:E9) -> 0.24478159 | F10: =SUM(F6:F9) -> 0.1
B11: Feasible under lockup? | E11: =IF(E10>=C4-0.000001,"YES","NO") -> YES
B13: 20% private allocation | C13: 0.2
B14: Sleeve | C14: Budget | D14: Headroom (sim) | E14: Effective budget | F14: Lockup-safe weight | G14: Breach prob. (sim)
B15: Private credit | C15: =Inputs!$C$29 -> 0.12 | D15: 1.377482 | E15: =C15/D15 -> 0.087115476 | F15: 0.087115 | G15: 0.0414
B16: Private equity | C16: =Inputs!$C$30 -> 0.07 | D16: 1.497642 | E16: =C16/D16 -> 0.046740142 | F16: 0.04674 | G16: 0.0483
B17: Real estate | C17: =Inputs!$C$31 -> 0.08 | D17: 1.441266 | E17: =C17/D17 -> 0.055506756 | F17: 0.055507 | G17: 0.0487
B18: Infrastructure | C18: =Inputs!$C$32 -> 0.08 | D18: 1.324936 | E18: =C18/D18 -> 0.060380275 | F18: 0.010638 | G18: 0
B19: Max feasible private (sum of effective budgets) | E19: =SUM(E15:E18) -> 0.24974265 | F19: =SUM(F15:F18) -> 0.2
B20: Feasible under lockup? | E20: =IF(E19>=C13-0.000001,"YES","NO") -> YES
B22: 30% private allocation | C22: 0.3
B23: Sleeve | C23: Budget | D23: Headroom (sim) | E23: Effective budget | F23: Lockup-safe weight | G23: Breach prob. (sim)
B24: Private credit | C24: =Inputs!$C$29 -> 0.12 | D24: 1.344665 | E24: =C24/D24 -> 0.089241558 | F24: n/a | G24: n/a
B25: Private equity | C25: =Inputs!$C$30 -> 0.07 | D25: 1.465975 | E25: =C25/D25 -> 0.047749791 | F25: n/a | G25: n/a
B26: Real estate | C26: =Inputs!$C$31 -> 0.08 | D26: 1.410926 | E26: =C26/D26 -> 0.056700351 | F26: n/a | G26: n/a
B27: Infrastructure | C27: =Inputs!$C$32 -> 0.08 | D27: 1.282488 | E27: =C27/D27 -> 0.062378751 | F27: n/a | G27: n/a
B28: Max feasible private (sum of effective budgets) | E28: =SUM(E24:E27) -> 0.25607045
B29: Feasible under lockup? | E29: =IF(E28>=C22-0.000001,"YES","NO") -> NO
B31: Chart data (links to the blocks above)
B32: Private allocation | C32: Target | D32: Max feasible under lockup
B33: 10% | C33: =C4 -> 0.1 | D33: =E10 -> 0.24478159
B34: 20% | C34: =C13 -> 0.2 | D34: =E19 -> 0.24974265
B35: 30% | C35: =C22 -> 0.3 | D35: =E28 -> 0.25607045
B39: Private sleeves can’t be sold for 3 years, so their weights can grow past their limits.
B40: Headroom = how much a sleeve’s weight can grow in a bad case (worst 5% of 10,000 simulations).
B41: Effective budget = budget ÷ headroom: the highest safe starting weight.
B42: If the effective budgets add up to at least the target, the allocation fits (YES). 30% does not.

Sheet Frontier
A1: Efficient frontier points (Python optimizer output)
A3: 60/40 building blocks | D3: With private sleeves | G3: With floor + lockup
A4: Volatility | B4: Return | D4: Volatility | E4: Return | G4: Volatility | H4: Return
A5: 0.0476 | B5: 0.0491 | D5: 0.041333 | E5: 0.054816 | G5: 0.041502 | H5: 0.053535
A6: 0.047816 | B6: 0.049877 | D6: 0.041433 | E6: 0.055555 | G6: 0.041565 | H6: 0.054643
A7: 0.048369 | B7: 0.050654 | D7: 0.041672 | E7: 0.056294 | G7: 0.04191 | H7: 0.055752
A8: 0.049245 | B8: 0.051431 | D8: 0.042018 | E8: 0.057033 | G8: 0.043158 | H8: 0.056861
A9: 0.050429 | B9: 0.052208 | D9: 0.042469 | E9: 0.057772 | G9: 0.045752 | H9: 0.057969
A10: 0.0519 | B10: 0.052984 | D10: 0.043021 | E10: 0.058511 | G10: 0.048855 | H10: 0.059078
A11: 0.053634 | B11: 0.053761 | D11: 0.043672 | E11: 0.05925 | G11: 0.052385 | H11: 0.060187
A12: 0.055606 | B12: 0.054538 | D12: 0.044415 | E12: 0.059989 | G12: 0.056253 | H12: 0.061295
A13: 0.057791 | B13: 0.055315 | D13: 0.045247 | E13: 0.060729 | G13: 0.060402 | H13: 0.062404
A14: 0.060168 | B14: 0.056092 | D14: 0.046263 | E14: 0.061468 | G14: 0.064779 | H14: 0.063513
A15: 0.062713 | B15: 0.056869 | D15: 0.048067 | E15: 0.062207 | G15: 0.069371 | H15: 0.064621
A16: 0.065408 | B16: 0.057646 | D16: 0.050252 | E16: 0.062946 | G16: 0.074136 | H16: 0.06573
... A29: 0.108261 | B29: 0.067746 | D29: 0.089386 | E29: 0.072553 | G29: 0.145445 | H29: 0.080143
A30: 0.111894 | B30: 0.068522 | D30: 0.092822 | E30: 0.073292
A31: 0.115552 | B31: 0.069299 | D31: 0.096287 | E31: 0.074031
A32: 0.119235 | B32: 0.070076 | D32: 0.09978 | E32: 0.07477
A33: 0.122939 | B33: 0.070853 | D33: 0.103296 | E33: 0.075509
A34: 0.126663 | B34: 0.07163 | D34: 0.106834 | E34: 0.076248
A35: 0.130406 | B35: 0.072407 | D35: 0.110392 | E35: 0.076987
A36: 0.134164 | B36: 0.073184 | D36: 0.113967 | E36: 0.077726
A37: 0.137939 | B37: 0.073961 | D37: 0.117559 | E37: 0.078465
A38: 0.141727 | B38: 0.074738 | D38: 0.121165 | E38: 0.079204
A39: 0.145528 | B39: 0.075515 | D39: 0.124785 | E39: 0.079943
A40: 0.149341 | B40: 0.076291 | D40: 0.128418 | E40: 0.080682
A41: 0.153165 | B41: 0.077068 | D41: 0.132061 | E41: 0.081421
... A44: 0.164695 | B44: 0.079399 | D44: 0.144887 | E44: 0.083638
